<?xml version="1.0"?>
<sdf version="1.6">
  <model name="two_wheel_robot">
    <static>false</static>

    <!-- Base Link -->
    <link name="base_link">
      <pose>0 0 0.1 0 0 0</pose>

      <inertial>
        <mass>5.0</mass>
        <inertia>
          <ixx>0.1</ixx><iyy>0.1</iyy><izz>0.1</izz>
          <ixy>0</ixy><ixz>0</ixz><iyz>0</iyz>
        </inertia>
      </inertial>

      <!-- Body -->
      <visual name="base_visual">
        <geometry>
          <box><size>0.4 0.3 0.15</size></box>
        </geometry>
        <material><ambient>0.2 0.5 0.8 1</ambient></material>
      </visual>

      <collision name="base_collision">
        <geometry>
          <box><size>0.4 0.3 0.15</size></box>
        </geometry>
      </collision>
    </link>

    <!-- Left Wheel -->
    <link name="left_wheel">
      <pose>0 0.18 0.05 1.5708 0 0</pose>

      <inertial>
        <mass>0.5</mass>
        <inertia><ixx>0.01</ixx><iyy>0.01</iyy><izz>0.01</izz></inertia>
      </inertial>
      <visual name="left_wheel_visual">
        <geometry>
          <cylinder><radius>0.05</radius><length>0.02</length></cylinder>
        </geometry>
        <material><ambient>0 0 0 1</ambient></material>
      </visual>
      <collision name="left_wheel_collision">
        <geometry>
          <cylinder><radius>0.05</radius><length>0.02</length></cylinder>
        </geometry>
      </collision>
    </link>

    <!-- Right Wheel -->
    <link name="right_wheel">
      <pose>0 -0.18 0.05 1.5708 0 0</pose>

      <inertial>
        <mass>0.5</mass>
        <inertia><ixx>0.01</ixx><iyy>0.01</iyy><izz>0.01</izz></inertia>
      </inertial>
      <visual name="right_wheel_visual">
        <geometry>
          <cylinder><radius>0.05</radius><length>0.02</length></cylinder>
        </geometry>
        <material><ambient>0 0 0 1</ambient></material>
      </visual>
      <collision name="right_wheel_collision">
        <geometry>
          <cylinder><radius>0.05</radius><length>0.02</length></cylinder>
        </geometry>
      </collision>
    </link>

    <!-- Joints -->
    <joint name="left_wheel_joint" type="revolute">
      <parent>base_link</parent>
      <child>left_wheel</child>
      <axis>
        <xyz>0 1 0</xyz>

        <limit><lower>-inf</lower><upper>inf</upper></limit>
      </axis>
    </joint>

    <joint name="right_wheel_joint" type="revolute">
      <parent>base_link</parent>
      <child>right_wheel</child>
      <axis>
        <xyz>0 1 0</xyz>

        <limit><lower>-inf</lower><upper>inf</upper></limit>
      </axis>
    </joint>

  <!-- Joint for LiDAR -->
<joint name="lidar_joint" type="fixed">
  <parent>base_link</parent>
  <child>lidar_link</child>
</joint>

<!-- Joint for IMU -->
<joint name="imu_joint" type="fixed">
  <parent>base_link</parent>
  <child>imu_link</child>
</joint>

    <!-- LiDAR -->
    <link name="lidar_link">
      <pose>0.15 0 0.19 0 0 0</pose>

      <visual name="lidar_visual">
        <geometry>
          <cylinder><radius>0.03</radius><length>0.04</length></cylinder>
        </geometry>
      </visual>

      <sensor name="lidar" type="ray">
      <topic>scan</topic>

        <update_rate>10</update_rate>
        <ray>
          <scan>
            <horizontal>
              <samples>360</samples>
              <resolution>1</resolution>
              <min_angle>-3.14</min_angle>
              <max_angle>3.14</max_angle>
            </horizontal>
          </scan>
          <range>
            <min>0.1</min>
            <max>5.0</max>
            <resolution>0.01</resolution>
          </range>
        </ray>
        <always_on>true</always_on>
        <visualize>true</visualize>

      <plugin name="gazebo_ros_lidar" filename="libgazebo_ros_ray_sensor.so">
        <ros>
          <namespace>/</namespace>
          <remapping>scan:=/scan</remapping>
        </ros>
      </plugin>

      </sensor>
    </link>

    <!-- IMU -->
    <link name="imu_link">
      <pose>0 0 0.15 0 0 0</pose>
      <visual name="imu_visual">
  <geometry>
    <box><size>0.05 0.05 0.03</size></box>
  </geometry>
  <material><ambient>1 0 0 1</ambient></material>
</visual>


  <inertial>
    <mass>0.01</mass>   <!-- very light sensor -->
    <inertia>
      <ixx>1e-6</ixx><iyy>1e-6</iyy><izz>1e-6</izz>
      <ixy>0</ixy><ixz>0</ixz><iyz>0</iyz>
    </inertia>
  </inertial>

      <sensor name="imu" type="imu">
        <always_on>true</always_on>
        <update_rate>100</update_rate>
        <plugin name="imu_plugin" filename="libgazebo_ros_imu_sensor.so">
  <ros>
    <namespace>/</namespace>
    <remapping>imu:=/imu</remapping>
  </ros>
</plugin>
      </sensor>
    </link>

    <pose>0 0 0 0 0 0</pose>

        <!-- Castor Wheel -->
    <link name="caster_wheel">
      <pose>0.15 0 0.03 0 0 0</pose>  <!-- behind robot, touching ground -->

      <inertial>
        <mass>0.2</mass>
        <inertia>
          <ixx>0.0001</ixx><iyy>0.0001</iyy><izz>0.0001</izz>
          <ixy>0</ixy><ixz>0</ixz><iyz>0</iyz>
        </inertia>
      </inertial>

      <collision name="caster_collision">
        <geometry>
          <sphere>
            <radius>0.03</radius>
          </sphere>
        </geometry>
        <surface>
          <friction>
            <ode>
              <mu>0.1</mu>
              <mu2>0.1</mu2>
            </ode>
          </friction>
        </surface>
      </collision>

      <visual name="caster_visual">
        <geometry>
          <sphere>
            <radius>0.03</radius>
          </sphere>
        </geometry>
        <material>
          <ambient>0.3 0.3 0.3 1</ambient>
        </material>
      </visual>
    </link>

    <!-- Castor joint -->
    <joint name="caster_joint" type="fixed">
      <parent>base_link</parent>
      <child>caster_wheel</child>
    </joint>

<!-- Differential Drive Plugin -->
<plugin name="diff_drive" filename="libgazebo_ros_diff_drive.so">
  <ros>
    <namespace>/</namespace>
  </ros>

  <!-- Wheel joints -->
  <left_joint>left_wheel_joint</left_joint>
  <right_joint>right_wheel_joint</right_joint>

  <!-- Wheel geometry -->
  <wheel_separation>0.36</wheel_separation>     <!-- distance between wheels (y-axis) -->
  <wheel_radius>0.05</wheel_radius>

  <!-- ROS interface -->
  <command_topic>/cmd_vel</command_topic>
  <odometry_topic>/odom</odometry_topic>
  <odometry_frame>odom</odometry_frame>
  <robot_base_frame>base_link</robot_base_frame>

  <!-- Movement tuning -->
  <publish_odom>true</publish_odom>
  <publish_tf>true</publish_tf>
  <velocity_multiplier>1.0</velocity_multiplier>

  <!-- Wheel constraints -->
  <max_wheel_torque>5.0</max_wheel_torque>
  <max_wheel_acceleration>2.0</max_wheel_acceleration>
</plugin>

  </model>
</sdf>
